<mujoco model='hand-relocate(v1.0)'>
    <worldbody>
        <!-- ======= TABLE  ======= -->
        <body name="table">
            <!-- <geom size="0.5 0.5 0.025" type="plane" material="table2d" />  -->
            <!-- Plane has better contacts -->
            <geom size="0.85 0.85 0.025" pos="0 0 0.025" type="box" material="tablecube" />
            <geom size="0.04 0.5" pos="0.4 0.4 -0.501" quat="0 1 0 0" type="cylinder" contype="0" conaffinity="0" />
            <geom size="0.04 0.5" pos="-0.4 0.4 -0.501" quat="0 1 0 0" type="cylinder" contype="0" conaffinity="0" />
            <geom size="0.04 0.5" pos="0.4 -0.4 -0.501" quat="0 1 0 0" type="cylinder" contype="0" conaffinity="0" />
            <geom size="0.04 0.5" pos="-0.4 -0.4 -0.501" quat="0 1 0 0" type="cylinder" contype="0" conaffinity="0" />
        </body>
        <!-- ======= MOCAP ======= -->
        <!-- <body name="vive_tracker" pos="0 -0.35 0.25" mocap="true">
            <inertial pos="0 0 0" mass="0.064" diaginertia="1.70667e-05 1.70667e-05 1.70667e-05" />
            <geom size="0.03 0.01" type="cylinder" contype="0" conaffinity="0" group="3" rgba="0.3 0.3 0.3 0.3" />
        </body> -->

        <!-- ======= HAND ======= -->
        <body name="arm_Link" pos="0.00 0 0" euler="0 0 0">
        <!-- <body name="arm_Link" pos="0.4784 -0.0643 0.3619" euler="1.5707963 1.5707963 3.1415926"> -->
            <!-- <inertial pos="2.28292e-06 -0.00195107 -0.0525061"  mass="0.122295" diaginertia="7.80442e-05 5.95552e-05 5.56013e-05" quat="0.456175 0.431743 0.51318 0.584935"/> -->
            <inertial pos="0 -0.002 -0.05" quat="0.456175 0.431743 0.51318 0.584935" mass="4" diaginertia="0.01 0.01 0.0075"/>
            <!-- <joint name="ARTx" pos="0 0 0" axis="0 0 1" type="slide" range="-0.5 0.5" damping="20" limited="true" margin="0.01" armature="0.001"  frictionloss="0.001"/>
            <joint name="ARTy" pos="0 0 0" axis="-1 0 0" type="slide" range="-0.2 0.8" damping="20" limited="true" margin="0.01" armature="0.001"  frictionloss="0.001"/>
            <joint name="ARTz" pos="0 0 0" axis="0 -1 0" type="slide" range="-0.3 0.5" damping="20" limited="true" margin="0.01" armature="0.001"  frictionloss="0.001"/>
            <joint name="ARRx" pos="0 0 0" axis="0 0 1" range="-.75 .75" damping="20" limited="true" margin="0.01" armature="0.001"  frictionloss="0.001"/>
            <joint name="ARRy" pos="0 0 0" axis="-1 0 0" range="-.75 .75" damping="20" limited="true" margin="0.01" armature="0.001"  frictionloss="0.001"/>
            <joint name="ARRz" pos="0 0 0" axis="0 -1 0" range="-.75 .75" damping="20" limited="true" margin="0.01" armature="0.001"  frictionloss="0.001"/> -->
            <joint name="ARTx" pos="0 0 0" axis="1 0 0" type="slide" range="-0.5 0.5" damping="20" limited="true" margin="0.01" armature="0.001"  frictionloss="0.001"/>
            <joint name="ARTy" pos="0 0 0" axis="0 1 0" type="slide" range="-0.5 0.5" damping="20" limited="true" margin="0.01" armature="0.001"  frictionloss="0.001"/>
            <joint name="ARTz" pos="0 0 0" axis="0 0 1" type="slide" range="-0.2 0.8" damping="20" limited="true" margin="0.01" armature="0.001"  frictionloss="0.001"/>
            <joint name="ARRx" pos="0 0 0" axis="1 0 0" range="-1.57 1.57" damping="20" limited="true" margin="0.01" armature="0.001"  frictionloss="0.001"/>
            <joint name="ARRy" pos="0 0 0" axis="0 1 0" range="-1.57 1.57" damping="20" limited="true" margin="0.01" armature="0.001"  frictionloss="0.001"/>
            <joint name="ARRz" pos="0 0 0" axis="0 0 1" range="-1.57 1.57" damping="20" limited="true" margin="0.01" armature="0.001"  frictionloss="0.001"/>
            <!-- <joint name="arm_joint" pos="0 0 0" axis="0 0 1" /> -->
            <!-- <geom type="mesh" contype="0" conaffinity="0" group="1" rgba="1 1 1 1" mesh="arm_Link" />
            <geom type="mesh" rgba="1 1 1 1" mesh="arm_Link" />
            <geom name="C_arm_Link" class="DC_Hand" size="0.05 0.033" pos="0 0 0.29" type="capsule" rgba="0.4 0.5 0.6 0.1" /> -->
            <geom name="V_arm_Link" class="D_Vizual" mesh="arm_Link" />
            <geom name="C_arm_Link" class="DC_Hand" type="mesh" mesh="arm_Link" />

            <body name="plam_Link" pos="0.0036705 0.0081778 0.027322">
                <!-- <inertial pos="-0.00227359 -0.00910821 0.0148966" quat="0.357839 0.60222 0.600298 0.385909" mass="0.0732237" diaginertia="7.58748e-05 4.25465e-05 3.65147e-05" /> -->
                <inertial pos="-0.00227359 -0.00910821 0.0148966" quat="0.357839 0.60222 0.600298 0.385909" mass="0.3" diaginertia="0.001 0.001 0.001" />
                <!-- <joint name="plam_joint" pos="0 0 0" axis="0 0 -1" /> -->
                <!-- <geom type="mesh" contype="0" conaffinity="0" group="1" rgba="1 1 1 1" mesh="plam_Link" />
                <geom type="mesh" rgba="1 1 1 1" mesh="plam_Link" />
                <geom name="C_palm0" class="DC_Hand" size="0.032 0.0111 0.049" pos="0.011 0 0.038" type="box" rgba="0.4 0.5 0.6 0.1" />
                <geom name="C_palm1" class="DC_Hand" size="0.011 0.0111 0.025" pos="-0.032 0 0.014" type="box" rgba="0.4 0.5 0.6 0.1" /> -->
                <geom name="V_plam_Link" class="D_Vizual" mesh="plam_Link" />
                <geom name="C_plam_Link" class="DC_Hand" type="mesh" mesh="plam_Link" />
                <site name="S_grasp"  type="sphere" rgba="1 1 1 1" size="0.01" pos="-0.005 0.04 0.035" quat="0.0087 -0.6 -0.0034 -0.81 "  group="5"/>  
                <site class="D_Touch" name="Tch_ffmetacarpal" size="0.009 0.007 0.009" pos="-0.03 -0.005 0.035"/>
                <site class="D_Touch" name="Tch_mfmetacarpal" size="0.009 0.007 0.009" pos="-0.01 -0.005 0.035"/>
                <site class="D_Touch" name="Tch_rfmetacarpal" size="0.009 0.007 0.009" pos="0.01 -0.005 0.035"/>
                <site class="D_Touch" name="Tch_lfmetacarpal" size="0.009 0.007 0.009" pos="0.03 -0.005 0.035"/>
                <site class="D_Touch" name="Tch_thmetacarpal" size="0.009 0.007 0.009" pos="-0.03 -0.005 0.01" euler="0 0 0"/>
                <site class="D_Touch" name="Tch_palm" size="0.02 0.01 0.015" pos="0.01 0.005 -0.01" euler="0 0 0"/>
                
                <body name="thumb1_Link" pos="-0.026788 0.0048941 -0.0194" quat="-2.91516e-07 0.0793628 0.996846 -3.66162e-06">
                    <!-- <inertial pos="0.0034687 0.000206586 -0.000326057" quat="0.456175 0.431743 0.51318 0.584935" mass="0.00162077" diaginertia="6.55549e-08 5.9013e-08 3.56846e-08" /> -->
                    <inertial pos="0.0034687 0.000206586 -0.000326057" quat="0.456175 0.431743 0.51318 0.584935" mass="0.002" diaginertia="1e-05 1e-05 1e-05" />
                    <joint name="THJ3" pos="0 0 0" axis="0 0 1" range="0 1.24" user="1120" limited="true" margin="0.01" armature="0.001" damping="0.05" frictionloss="0.001" />
                    <!-- <geom type="mesh" contype="0" conaffinity="0" group="1" rgba="1 1 1 1" mesh="thumb1_Link" />
                    <geom type="mesh" rgba="1 1 1 1" mesh="thumb1_Link" />
                    <geom name="C_thproximal" class="DC_Hand" size="0.013 0.019" pos="0 0 0.019" type="capsule" rgba="0.4 0.5 0.6 0.1" /> -->
                    <geom name="V_thumb1_Link" class="D_Vizual" mesh="thumb1_Link" />
                    <geom name="C_thumb1_Link" class="DC_Hand" type="mesh" mesh="thumb1_Link" />
                    <site class="D_Force" name="F_thproximal" size="0.005 0.005 0.005" pos="0 0 0"  />

                    <body name="thumb2_Link" pos="0.010824 0.00096965 0.00039868" quat="-2.59734e-06 2.59735e-06 -0.707108 0.707105">
                        <!-- <inertial pos="-0.0220039 0.01313 -5.3962e-08" quat="0.214559 0.673767 -0.214575 0.673766" mass="0.0261102" diaginertia="7.93935e-06 6.72645e-06 2.40904e-06" /> -->
                        <inertial pos="-0.0220039 0.01313 -5.3962e-08" quat="0.214559 0.673767 -0.214575 0.673766" mass="0.032" diaginertia="1e-05 1e-05 1e-05" />
                        <joint name="THJ2" pos="0 0 0" axis="0 0 -1" range="0 0.262" user="1119" limited="true" margin="0.01" armature="0.001" damping="0.05" frictionloss="0.001" />
                        <!-- <geom type="mesh" contype="0" conaffinity="0" group="1" rgba="1 1 1 1" mesh="thumb2_Link" />
                        <geom type="mesh" rgba="1 1 1 1" mesh="thumb2_Link" /> -->
                        <geom name="V_thumb2_Link" class="D_Vizual" mesh="thumb2_Link" />
                        <geom name="C_thumb2_Link" class="DC_Hand" type="mesh" mesh="thumb2_Link" />
                        <site class="D_Touch" name="Tch_thproximal" size="0.012 0.022 0.007" pos="-0.02 0.015 0" euler="0 0 1.0" />
                        <site class="D_Force" name="F_thmiddle" size="0.005 0.005 0.005" pos="0 0 0"  />

                        <body name="thumb3_Link" pos="-0.044366 0.034168 0">
                            <!-- <inertial pos="-0.0108321 0.00273614 7.68567e-09" quat="0.336029 0.622133 -0.336074 0.622165" mass="0.00762419" diaginertia="8.63242e-07 8.11269e-07 3.50826e-07" /> -->
                            <inertial pos="-0.0108321 0.00273614 7.68567e-09" quat="0.336029 0.622133 -0.336074 0.622165" mass="0.016" diaginertia="1e-05 1e-05 1e-05" />
                            <joint name="THJ1" pos="0 0 0" axis="0 0 -1" range="0 0.524" user="1118" limited="true" margin="0.01" armature="0.001" damping="0.05" frictionloss="0.001" />
                            <!-- <geom type="mesh" contype="0" conaffinity="0" group="1" rgba="1 1 1 1" mesh="thumb3_Link" />
                            <geom type="mesh" rgba="1 1 1 1" mesh="thumb3_Link" />
                            <geom name="C_thmiddle" class="DC_Hand" size="0.011 0.016" pos="0 0 0.016" type="capsule" /> -->
                            <geom name="V_thumb3_Link" class="D_Vizual" mesh="thumb3_Link" />
                            <geom name="C_thumb3_Link" class="DC_Hand" type="mesh" mesh="thumb3_Link" />
                            <site class="D_Touch" name="Tch_thmiddle" pos="-0.005 0.005 0" size="0.006 0.008 0.006" euler="0 0 0.85" />

                            <body name="thumb4_Link" pos="-0.017535 0.014361 0">
                                <!-- <inertial pos="-0.00814856 0.00720893 -6.48852e-08" quat="0.335515 0.622372 -0.335637 0.622438" mass="0.00320276" diaginertia="1.86521e-07 1.79941e-07 7.65874e-08" /> -->
                                <inertial pos="-0.00814856 0.00720893 -6.48852e-08" quat="0.335515 0.622372 -0.335637 0.622438" mass="0.008" diaginertia="1e-05 1e-05 1e-05" />
                                <joint name="THJ0" pos="0 0 0" axis="0 0 -1" range="0 0.6" user="1117" limited="true" margin="0.01" armature="0.001" damping="0.05" frictionloss="0.001" />
                                <!-- <geom type="mesh" contype="0" conaffinity="0" group="1" rgba="1 1 1 1" mesh="thumb4_Link" />
                                <geom type="mesh" rgba="1 1 1 1" mesh="thumb4_Link" />
                                <geom name="C_thdistal" class="DC_Hand" size="0.00918 0.013" pos="0 0 0.013" type="capsule" condim="4" /> -->
                                <geom name="V_thumb4_Link" class="D_Vizual" mesh="thumb4_Link" />
                                <geom name="C_thumb4_Link" class="DC_Hand" type="mesh" mesh="thumb4_Link" />
                                <site name="S_thtip" pos="-0.005 0.008 0" group="3" />
                                <site name="Tch_thtip" class="D_Touch" pos="-0.007 0.009 0" size="0.006 0.01 0.006" euler="0 0 0.7" />
                            </body>
                        </body>
                    </body>
                </body>
                
                <body name="index1_Link" pos="-0.031827 -0.011748 0.057087" quat="0.707105 0.707108 0 0">
                    <!-- <inertial pos="-0.000474749 0.0135945 0.00644797" quat="0.464193 0.535148 -0.51679 0.480697" mass="0.000437226" diaginertia="8.4587e-09 7.25737e-09 2.89284e-09" /> -->
                    <inertial pos="-0.000474749 0.0135945 0.00644797" quat="0.464193 0.535148 -0.51679 0.480697" mass="0.016" diaginertia="1e-05 1e-05 1e-05" />
                    <joint name="FFJ2" pos="0 0 0" axis="-0.999391 -0.0348995 0" range="0 1.571" user="1102" limited="true" margin="0.01" armature="0.001" damping="0.05" frictionloss="0.001" />
                    <!-- <geom type="mesh" contype="0" conaffinity="0" group="1" rgba="1 1 1 1" mesh="index1_Link" />
                    <geom type="mesh" rgba="1 1 1 1" mesh="index1_Link" />
                    <geom name="C_ffproximal" class="DC_Hand" size="0.01 0.0225" pos="0 0 0.0225" type="capsule" /> -->
                    <geom name="V_index1_Link" class="D_Vizual" mesh="index1_Link" />
                    <geom name="C_index1_Link" class="DC_Hand" type="mesh" mesh="index1_Link" />
                    <site class="D_Touch" name="Tch_ffproximal" size="0.009 0.007 0.007" pos="0 0.015 0" euler="1.57 1.57 0" />
                    <site class="D_Force" name="F_ffproximal" size="0.005 0.005 0.005" pos="0 0 0"  />
                    
                    <body name="index2_Link" pos="-0.0011368 0.032553 -0.0011797" quat="0.491197 0.491199 0.50865 0.508648">
                        <!-- <inertial pos="0.0182221 0.00351287 -2.48037e-08" quat="0.0243998 0.706686 -0.0243998 0.706686" mass="0.00444704" diaginertia="7.46238e-07 7.36659e-07 7.84594e-08" /> -->
                        <inertial pos="0.0182221 0.00351287 -2.48037e-08" quat="0.0243998 0.706686 -0.0243998 0.706686" mass="0.016" diaginertia="1e-05 1e-05 1e-05" />
                        <joint name="FFJ1" pos="0 0 0" axis="0 0 -1" range="0 1.57" user="1101" limited="true" margin="0.01" armature="0.001" damping="0.05" frictionloss="0.001" />
                        <!-- <geom type="mesh" rgba="1 1 1 1" mesh="index2_Link" />
                        <geom name="C_ffmiddle" class="DC_Hand" size="0.00805 0.0125" pos="0 0 0.0125" type="capsule" /> -->
                        <geom name="V_index2_Link" class="D_Vizual" mesh="index2_Link" />
                        <geom name="C_index2_Link" class="DC_Hand" type="mesh" mesh="index2_Link" />
                        <site class="D_Touch" name="Tch_ffmiddle" size="0.009 0.002 0.007" pos="0.012 0 0"/>
                        <site name="S_fftip" pos="0.035 0 0" group="3" />
                        <site name="Tch_fftip" class="D_Touch" size="0.009 0.002 0.007" pos="0.035 0 0" />
                    </body>
                </body>
                
                <body name="middle1_Link" pos="-0.012505 -0.011748 0.05745" quat="0.499998 0.5 0.500002 0.5">
                    <!-- <inertial pos="-0.00610857 0.0137585 -1.80236e-08" quat="0.706508 0.706508 0.0291018 0.0291018" mass="0.000437227" diaginertia="8.45892e-09 7.25758e-09 2.89284e-09" /> -->
                    <inertial pos="-0.00610857 0.0137585 -1.80236e-08" quat="0.706508 0.706508 0.0291018 0.0291018" mass="0.016" diaginertia="1e-05 1e-05 1e-05" />
                    <joint name="MFJ2" pos="0 0 0" axis="0 0 -1" range="0 1.571" user="1106" limited="true" margin="0.01" armature="0.001" damping="0.05" frictionloss="0.001" />
                    <!-- <geom type="mesh" contype="0" conaffinity="0" group="1" rgba="1 1 1 1" mesh="middle1_Link" />
                    <geom type="mesh" rgba="1 1 1 1" mesh="middle1_Link" />
                    <geom name="C_mfproximal" class="DC_Hand" size="0.01 0.0225" pos="0 0 0.0225" type="capsule" /> -->
                    <geom name="V_middle1_Link" class="D_Vizual" mesh="middle1_Link" />
                    <geom name="C_middle1_Link" class="DC_Hand" type="mesh" mesh="middle1_Link" />
                    <site class="D_Touch" name="Tch_mfproximal" size="0.009 0.007 0.007" pos="0 0.015 0" euler="0 0 1.57" />
                    <site class="D_Force" name="F_mfproximal" size="0.005 0.005 0.005" pos="0 0 0" euler="0 0 0" />
                    
                    <body name="middle2_Link" pos="0.0019785 0.032536 0">
                        <!-- <inertial pos="-0.00341407 0.0182408 -2.82103e-08" quat="0.518261 0.481047 -0.518261 0.481047" mass="0.00444703" diaginertia="7.46236e-07 7.36658e-07 7.84593e-08" /> -->
                        <inertial pos="-0.00341407 0.0182408 -2.82103e-08" quat="0.518261 0.481047 -0.518261 0.481047" mass="0.016" diaginertia="1e-05 1e-05 1e-05" />
                        <joint name="MFJ1" pos="0 0 0" axis="0 0 -1" range="0 1.571" user="1105" limited="true" margin="0.01" armature="0.001" damping="0.05" frictionloss="0.001" />
                        <!-- <geom type="mesh" contype="0" conaffinity="0" group="1" rgba="1 1 1 1" mesh="middle2_Link" />
                        <geom type="mesh" rgba="1 1 1 1" mesh="middle2_Link" />
                        <geom name="C_mfmiddle" class="DC_Hand" size="0.00805 0.0125" pos="0 0 0.0125" type="capsule" /> -->
                        <geom name="V_middle2_Link" class="D_Vizual" mesh="middle2_Link" />
                        <geom name="C_middle2_Link" class="DC_Hand" type="mesh" mesh="middle2_Link" />
                        <site class="D_Touch" name="Tch_mfmiddle" size="0.009 0.002 0.007" pos="0 0.012 0" euler="0 0 1.57" />
                        <site name="S_mftip" pos="0 0.035 0" euler="0 0 1.57" group="3" />
                        <site name="Tch_mftip" class="D_Touch" size="0.009 0.002 0.007" pos="0 0.035 0" euler="0 0 1.57" />
                    </body>
                </body>

                <body name="ring1_Link" pos="0.0067237 -0.011748 0.056946" quat="-2.66449e-06 -0.725387 2.52842e-06 -0.688341">
                    <!-- <inertial pos="0.0138995 0.0057807 -1.24247e-08" quat="0.48513 0.48513 0.51444 0.51444" mass="0.000437227" diaginertia="8.45894e-09 7.25758e-09 2.89282e-09" /> -->
                    <inertial pos="0.0138995 0.0057807 -1.24247e-08" quat="0.48513 0.48513 0.51444 0.51444" mass="0.016" diaginertia="1e-05 1e-05 1e-05" />
                    <joint name="RFJ2" pos="0 0 0" axis="0 0 -1" range="0 1.571" user="1110" limited="true" margin="0.01" armature="0.001" damping="0.05" frictionloss="0.001" />
                    <!-- <geom type="mesh" contype="0" conaffinity="0" group="1" rgba="1 1 1 1" mesh="ring1_Link" />
                    <geom type="mesh" rgba="1 1 1 1" mesh="ring1_Link" />
                    <geom name="C_rfproximal" class="DC_Hand" size="0.01 0.0225" pos="0 0 0.0225" type="capsule" /> -->
                    <geom name="V_ring1_Link" class="D_Vizual" mesh="ring1_Link" />
                    <geom name="C_ring1_Link" class="DC_Hand" type="mesh" mesh="ring1_Link" />
                    <site class="D_Touch" name="Tch_rfproximal" size="0.009 0.007 0.007" pos="0.015 0 0"/>
                    <site class="D_Force" name="F_rfproximal" size="0.005 0.005 0.005" pos="0 0 0"/>

                    
                    <body name="ring2_Link" pos="0.032486 -0.0027215 0">
                        <!-- <inertial pos="0.0181026 0.00408407 -2.88999e-08" quat="0.0132857 0.706981 -0.0132856 0.706983" mass="0.00444702" diaginertia="7.46236e-07 7.36657e-07 7.8459e-08" /> -->
                        <inertial pos="0.0181026 0.00408407 -2.88999e-08" quat="0.0132857 0.706981 -0.0132856 0.706983" mass="0.016" diaginertia="1e-05 1e-05 1e-05" />
                        <joint name="RFJ1" pos="0 0 0" axis="0 0 -1" range="0 1.571" user="1109" limited="true" margin="0.01" armature="0.001" damping="0.05" frictionloss="0.001" />
                        <!-- <geom type="mesh" contype="0" conaffinity="0" group="1" rgba="1 1 1 1" mesh="ring2_Link" />
                        <geom type="mesh" rgba="1 1 1 1" mesh="ring2_Link" />
                        <geom name="C_rfmiddle" class="DC_Hand" size="0.00805 0.0125" pos="0 0 0.0125" type="capsule" /> -->
                        <geom name="V_ring2_Link" class="D_Vizual" mesh="ring2_Link" />
                        <geom name="C_ring2_Link" class="DC_Hand" type="mesh" mesh="ring2_Link" />
                        <site class="D_Touch" name="Tch_rfmiddle" size="0.009 0.002 0.007" pos="0.012 0 0"/>
                        <site name="S_rftip" pos="0.035 0 0" group="3" />
                        <site name="Tch_rftip" class="D_Touch" size="0.009 0.002 0.007" pos="0.035 0 0" />
                    </body>
                </body>
                
                <body name="pink1_Link" pos="0.0259 -0.011748 0.055437" quat="0.47315 0.525478 0.52548 0.473152">
                    <!-- <inertial pos="-0.0059042 0.0138475 -8.84113e-09" quat="0.706704 0.706704 0.0238713 0.0238713" mass="0.000437226" diaginertia="8.45892e-09 7.25757e-09 2.89282e-09" /> -->
                    <inertial pos="-0.0059042 0.0138475 -8.84113e-09" quat="0.706704 0.706704 0.0238713 0.0238713" mass="0.016" diaginertia="1e-05 1e-05 1e-05" />
                    <joint name="LFJ2" pos="0 0 0" axis="0 0 -1" range="0 1.571" user="1114" limited="true" margin="0.01" armature="0.001" damping="0.05" frictionloss="0.001" />
                    <!-- <geom type="mesh" contype="0" conaffinity="0" group="1" rgba="1 1 1 1" mesh="pink1_Link" />
                    <geom type="mesh" rgba="1 1 1 1" mesh="pink1_Link" />
                    <geom name="C_lfproximal" class="DC_Hand" size="0.01 0.0225" pos="0 0 0.0225" type="capsule" /> -->
                    <geom name="V_pink1_Link" class="D_Vizual" mesh="pink1_Link" />
                    <geom name="C_pink1_Link" class="DC_Hand" type="mesh" mesh="pink1_Link" />
                    <site class="D_Touch" name="Tch_lfproximal" size="0.009 0.007 0.007" pos="0 0.015 0" euler="0 0 1.57" />
                    <site class="D_Force" name="F_lfproximal" size="0.005 0.005 0.005" pos="0 0 0"  />

                    <body name="pink2_Link" pos="0.0024443 0.0325 0" quat="0.707105 0 0 0.707108">
                        <!-- <inertial pos="0.014693 0.00460171 -3.02204e-05" quat="-0.0059368 0.707708 -0.00866201 0.706427" mass="0.00357993" diaginertia="4.28378e-07 4.22461e-07 6.14774e-08" /> -->
                        <inertial pos="0.014693 0.00460171 -3.02204e-05" quat="-0.0059368 0.707708 -0.00866201 0.706427" mass="0.016" diaginertia="1e-05 1e-05 1e-05" />
                        <joint name="LFJ1" pos="0 0 0" axis="0 0 -1" range="0 1.571" user="1113" limited="true" margin="0.01" armature="0.001" damping="0.05" frictionloss="0.001" />
                        <!-- <geom type="mesh" contype="0" conaffinity="0" group="1" rgba="1 1 1 1" mesh="pink2_Link" />
                        <geom type="mesh" rgba="1 1 1 1" mesh="pink2_Link" />
                        <geom name="C_lfmiddle" class="DC_Hand" size="0.00805 0.0125" pos="0 0 0.0125" type="capsule" /> -->
                        <geom name="V_pink2_Link" class="D_Vizual" mesh="pink2_Link" />
                        <geom name="C_pink2_Link" class="DC_Hand" type="mesh" mesh="pink2_Link" />
                        <site class="D_Touch" name="Tch_lfmiddle" size="0.009 0.002 0.007" pos="0.012 0 0"/>
                        <site name="S_lftip" pos="0.03 0 0" group="3" />
                        <site name="Tch_lftip" class="D_Touch" size="0.007 0.002 0.007" pos="0.03 0 0" />
                    </body>
                </body>
            </body>
        </body>
        <!-- ======= DESTINATION ======= -->
        <site name="target" pos="0 0 0" size="0.07" rgba="0 1 0 0.125" />

        <!-- ======= OBJECT ======= -->
        <body name="Object" pos="0 0 0" user="1001 0 2003 27 0 0 0.06 0 0" >
            <inertial pos="0 0 0" mass="0.179594" diaginertia="1e-03 1e-03 1e-03" />
            <joint name="OBJTx" pos="0 0 0" axis="1 0 0" type="slide" limited="true" damping="0.01" range="-0.5 0.5"/>
            <joint name="OBJTy" pos="0 0 0" axis="0 1 0" type="slide" limited="true" damping="0.01" range="-0.5 0.5"/>
            <joint name="OBJTz" pos="0 0 0" axis="0 0 1" type="slide" limited="true" damping="0.01" range="-0.5 0.5"/>
            <joint name="OBJRx" pos="0 0 0" axis="1 0 0" limited="false" damping="0.5" />
            <joint name="OBJRy" pos="0 0 0" axis="0 1 0" limited="false" damping="0.5" />
            <joint name="OBJRz" pos="0 0 0" axis="0 0 1" limited="false" damping="0.5" />
            <!-- OBJRx OBJRy OBJRz damping 小于0.5 训练时就会报QACC错 
            阻尼适用于该接头产生的所有自由度。与摩擦损失不同，摩擦损失由 约束求解器，阻尼只是速度线性的力。它包含在被动力中。尽管如此 简单、较大的阻尼值会使数值积分器不稳定，这就是我们的欧拉积分器处理 隐式阻尼。-->
            <!-- <geom name="sphere" size="0.035" solimp="2.0095 2.009 2.001" solref="0.001" condim="4"  /> -->
            <geom name="sphere" size="0.045" condim="4" />

        </body>

        <!-- Camera for the VIL paper -->
        <!-- <camera name="fixed" pos="0 -0.7 0.7" quat="0.92388 0.382683 0 0" />
        <camera name="vil_camera" pos="0 -1.2 1.2" quat="0.92388 0.382683 0 0" />
        <camera name="view_1" pos="-0.8 -0.8 0.8" euler="0.785 -0.785 -0.785" />
        <camera name="view_2" pos="0 0.5 0.2" euler="-1.57 0 3.14" />
        <camera name="view_3" pos="0 0.2 -0.2" euler="-2.35 0 3.14" />
        <camera name="view_4" pos="0.8 -0.8 0.8" euler="0.785 0.785 0.785" />
        <camera name="view_5" pos="0 -0.25 -0.4" euler="-3.2 0 3.14" />
        <camera name="top" pos="0 0 1.5" euler="0 0 3.14" /> -->

        <!-- ======= ROOM ======= -->
        <!-- <body name="room" pos="0 0 -.7" childclass="scene">
            <geom name="room" class='scene' pos="0 0 0" type="mesh" mesh="room" rgba=".3 .3 .3 1" euler="-.0 0 3.14"/>
            <geom name="floor" class='scene' pos="0 0 0.001" size="3 2.5 .1" conaffinity="1" contype="1" type="plane" material="MatPlane" condim="3"/>
            <geom name="lamp" class='scene' pos="2.604 2.1 1.65" type="cylinder" size=".3 .2" rgba="2 1.6 0 .6" />
            <light directional='false' diffuse='2 1.6 0' specular='0.03 0.03 0.03' pos='2.604 2.1 1.5' dir='0 0 -1' cutoff="90" exponent="5"/>
        </body> -->

        <!-- <light directional='false' diffuse='.8 .8 .8' specular='0.03 0.03 0.03' pos='-1 -1.0 3.0' dir='1 1.0 -3'/> -->
        <light directional='false' diffuse='.7 .7 .7' specular='0.03 0.03 0.03' pos='-1 -1.0 4.0' dir='1 1.0 -4'/>
        <geom name='ground' size="1.5 1.5 0.25" pos="0 0 -1" type="plane" contype="1" conaffinity="0" material="groundplane" />
    </worldbody>

    <!-- ======= actuator ======= -->
    <actuator>
        <general name="A_ARTx" joint="ARTx" ctrlrange="-0.5 0.5" biastype="affine" gainprm="500 0 0" biasprm="0 -200 0" />
        <general name="A_ARTy" joint="ARTy" ctrlrange="-0.5 0.5" biastype="affine" gainprm="500 0 0" biasprm="0 -200 0" />
        <general name="A_ARTz" joint="ARTz" ctrlrange="-0.5 0.5" biastype="affine" gainprm="500 0 0" biasprm="0 -200 0" />
        <general name="A_ARRx" joint="ARRx" ctrlrange="-.75 .75" biastype="affine" gainprm="500 0 0" biasprm="0 -200 0" />
        <general name="A_ARRy" joint="ARRy" ctrlrange="-.75 .75" biastype="affine" gainprm="500 0 0" biasprm="0 -200 0" />
        <general name="A_ARRz" joint="ARRz" ctrlrange="-.75 .75" biastype="affine" gainprm="500 0 0" biasprm="0 -200 0" />
    </actuator>

    <include file='hand_assets_1.xml'/>

</mujoco>